[2023-09-28T08:30:39.789+0000] {taskinstance.py:1157} INFO - Dependencies all met for dep_context=non-requeueable deps ti=<TaskInstance: user_processing.extract_user scheduled__2023-09-27T00:00:00+00:00 [queued]>
[2023-09-28T08:30:39.792+0000] {taskinstance.py:1157} INFO - Dependencies all met for dep_context=requeueable deps ti=<TaskInstance: user_processing.extract_user scheduled__2023-09-27T00:00:00+00:00 [queued]>
[2023-09-28T08:30:39.793+0000] {taskinstance.py:1359} INFO - Starting attempt 1 of 1
[2023-09-28T08:30:39.797+0000] {taskinstance.py:1380} INFO - Executing <Task(SimpleHttpOperator): extract_user> on 2023-09-27 00:00:00+00:00
[2023-09-28T08:30:39.801+0000] {standard_task_runner.py:57} INFO - Started process 228 to run task
[2023-09-28T08:30:39.804+0000] {standard_task_runner.py:84} INFO - Running: ['***', 'tasks', 'run', 'user_processing', 'extract_user', 'scheduled__2023-09-27T00:00:00+00:00', '--job-id', '29', '--raw', '--subdir', 'DAGS_FOLDER/user_processing.py', '--cfg-path', '/tmp/tmppkh_ptab']
[2023-09-28T08:30:39.805+0000] {standard_task_runner.py:85} INFO - Job 29: Subtask extract_user
[2023-09-28T08:30:39.827+0000] {task_command.py:415} INFO - Running <TaskInstance: user_processing.extract_user scheduled__2023-09-27T00:00:00+00:00 [running]> on host 95f0659b2457
[2023-09-28T08:30:39.859+0000] {taskinstance.py:1660} INFO - Exporting env vars: AIRFLOW_CTX_DAG_OWNER='***' AIRFLOW_CTX_DAG_ID='user_processing' AIRFLOW_CTX_TASK_ID='extract_user' AIRFLOW_CTX_EXECUTION_DATE='2023-09-27T00:00:00+00:00' AIRFLOW_CTX_TRY_NUMBER='1' AIRFLOW_CTX_DAG_RUN_ID='scheduled__2023-09-27T00:00:00+00:00'
[2023-09-28T08:30:39.861+0000] {http.py:143} INFO - Calling HTTP method
[2023-09-28T08:30:39.867+0000] {taskinstance.py:1935} ERROR - Task failed with exception
Traceback (most recent call last):
  File "/home/airflow/.local/lib/python3.8/site-packages/airflow/providers/http/operators/http.py", line 145, in execute
    response = http.run(self.endpoint, self.data, self.headers, self.extra_options)
  File "/home/airflow/.local/lib/python3.8/site-packages/airflow/providers/http/hooks/http.py", line 145, in run
    session = self.get_conn(headers)
  File "/home/airflow/.local/lib/python3.8/site-packages/airflow/providers/http/hooks/http.py", line 98, in get_conn
    conn = self.get_connection(self.http_conn_id)
  File "/home/airflow/.local/lib/python3.8/site-packages/airflow/hooks/base.py", line 72, in get_connection
    conn = Connection.get_connection_from_secrets(conn_id)
  File "/home/airflow/.local/lib/python3.8/site-packages/airflow/models/connection.py", line 477, in get_connection_from_secrets
    raise AirflowNotFoundException(f"The conn_id `{conn_id}` isn't defined")
airflow.exceptions.AirflowNotFoundException: The conn_id `user_api` isn't defined
[2023-09-28T08:30:39.869+0000] {taskinstance.py:1398} INFO - Marking task as FAILED. dag_id=user_processing, task_id=extract_user, execution_date=20230927T000000, start_date=20230928T083039, end_date=20230928T083039
[2023-09-28T08:30:39.873+0000] {standard_task_runner.py:104} ERROR - Failed to execute job 29 for task extract_user (The conn_id `user_api` isn't defined; 228)
[2023-09-28T08:30:39.896+0000] {local_task_job_runner.py:228} INFO - Task exited with return code 1
[2023-09-28T08:30:39.906+0000] {taskinstance.py:2776} INFO - 0 downstream tasks scheduled from follow-on schedule check
